Workbook
Name B: #REF!

Sheet EvaluationSheet 48Gy4F 60Gy5F
B1: NOTE: Must fill in information in YELLOW cells with "??". | H1: Use the ORIGINAL file for each NEW PLAN or modification
G2: SABR Plan Evaluation Sheet for 12Gy/fr Schedules (48 Gy in 4F) or (60Gy/5F)
G3: (Tumours located within the lung parenchyma, away from the OAR’s and chest wall)
C4: Patient: | D4: ?? | F4: Prescription Dose (cGy): | H4: ?? | K4: Site: | L4: ?? | O4: =C4 -> Patient: | P4: =D4 -> ??
C5: CR#: | D5: ?? | F5: Fractions: | H5: ?? | K5: Plan Name: | L5: ?? | O5: =C5 -> CR#: | P5: =D5 -> ??
B6: Target/OAR Volumes: | O6: =K4 -> Site: | P6: =L4 -> ??
C7: GTV Volume (cc) | G7: ?? | O7: =K5 -> Plan Name: | P7: =L5 -> ??
C8: ITV Volume (cc): | G8: ?? | O8: =F4 -> Prescription Dose (cGy): | P8: =H4 -> ??
C9: PTV Volume (cc) | G9: ?? | O9: =F5 -> Fractions: | P9: =H5 -> ??
C10: Total Lung Volume (cc) | G10: ?? | O10: =C7 -> GTV Volume (cc) | P10: =G7 -> ??
B11: Normalization: | E11: 100% Dose covers 95% of Target Volume | O11: =C8 -> ITV Volume (cc): | P11: =G8 -> ??
G12: Ref Dose (%) / | H12: Calculated Value | K12: Protocol | L12: Acceptable | M12: Comments | O12: =C9 -> PTV Volume (cc) | P12: =G9 -> ??
G13: Ref Volume (cc) | K13: Requirement | O13: =C10 -> Total Lung Volume (cc) | P13: =G10 -> ??
C14: Plan Normalization Value (%) | G14: ?? | K14: 60%-95% | L14: =IF(G14="??","??",IF((AND((G14>59.99%),(G14<95.01%))),"Yes", "No")) -> ?? | M14: See "Prescription" in Eclipse | O14: =C14 -> Plan Normalization Value (%) | P14: =G14 -> ??
B16: PTV Dose Inhomogeneity: | O16: =C17 -> PTV- Minimum Dose (%) | P16: =G17 -> ??
C17: PTV- Minimum Dose (%) | G17: ?? | K17: 60%-95% | L17: =IF(G17="??","??",IF((AND((G17>=60%),(G17<=95%))),"Yes", "No")) -> ?? | O17: =C18 -> PTV - V100(%) | P17: =G18 -> ??
C18: PTV - V100(%) | G18: ?? | K18: 0.95 | L18: =IF(G18="??","??",(IF(G18>=95%,"Yes","No"))) -> ?? | M18: PTV (V48Gy) | O18: =C19 -> PTV - V90 (%) | P18: =G19 -> ??
C19: PTV - V90 (%) | G19: ?? | K19: 0.99 | L19: =IF(G19="??","??",(IF(G19>=99%,"Yes","No"))) -> ?? | M19: PTV (V43.2Gy) | O19: =CONCATENATE(C21," ",D21) -> Location V105% - PTV (cc) = | P19: =G21 -> ??
B20: HIGH Dose Spillage: | O20: =CONCATENATE(C22," ",D22) -> Volume V100% (cc) = | P20: =G22 -> ??
C21: Location | D21: V105% - PTV (cc) = | G21: ?? | H21: =IFERROR(G21/G9,"??") -> ?? | K21: <15% | L21: =IF(G21="??","??",IF(H21<15%,"Yes","No")) -> ?? | M21: Volume of the structure (Dose 105% - PTV), D105% = 50.4 Gy | O21: =CONCATENATE(C24," ",D24) -> Location D³2cm (%) = | P21: =G24 -> ??
C22: Volume | D22: V100% (cc) = | G22: ?? | H22: =IFERROR('Calculations 48Gy4F_ or_ 60Gy5F'!J31,"??") -> ?? | K22: <1.2 | L22: ='Calculations 48Gy4F_ or_ 60Gy5F'!K31 -> ?? | M22: Ratio VD100%/VPTV (On DVH see BODY volume for 100% prescription dose) | O22: =C25 -> Volume | P22: =G25 -> ??
B23: LOW Dose Spillage: | O23: =C29 -> Mean Dose (contralateral lung) | P23: =G29 -> ??
C24: Location | D24: D³2cm (%) = | G24: ?? | K24: =IFERROR('Calculations 48Gy4F_ or_ 60Gy5F'!L27/100,"") | L24: ='Calculations 48Gy4F_ or_ 60Gy5F'!K33 -> ?? | M24: Max dose (in %) ³2cm from PTV (structure BODY-(PTV+2cm)), should be £ R50 value in Table 1, MINOR deviation acceptable | O24: =C30 -> Mean Dose (Total lung) | P24: =G30 -> ??
C25: Volume | D25: V50% (cc) = | G25: ?? | H25: =IFERROR('Calculations 48Gy4F_ or_ 60Gy5F'!J32,"??") -> ?? | K25: =IFERROR('Calculations 48Gy4F_ or_ 60Gy5F'!I27,"") | L25: =IFERROR('Calculations 48Gy4F_ or_ 60Gy5F'!K32,"??") -> ?? | M25: Ratio VD50%/VPTV should be£ R50 value in Table 1, MINOR deviation acceptable | O25: =C31 -> V20 (Total Lung) in % | P25: =G31 -> ??
B26: DOSE TO OARs | G26: Maximum Dose (cGy) | H26: Calculated Value | K26: Tolerance | O26: =CONCATENATE(C32," ",F32) -> Lung-Basic Function | P26: =G32 -> ??
G27: / Volume (cc) | K27: (cGy) / (cc) | O27: =CONCATENATE(C33," ",F33) -> Lung-Pneumonitis | P27: =G33 -> ??
C28: Lung Dose | O28: =CONCATENATE(C35," ",F35) -> Aorta (max point dose) | P28: =G35 -> ??
C29: Mean Dose (contralateral lung) | G29: ?? | L29: ?? | O29: =CONCATENATE(C35," ",F36) -> Aorta V40Gy= | P29: =G36 -> ??
C30: Mean Dose (Total lung) | G30: ?? | L30: ?? | O30: =CONCATENATE(C37," ",F37) -> Artery-Pulmonary (max point dose) | P30: =G37 -> ??
C31: V20 (Total Lung) in % | E31: V20Gy (%) = | G31: ?? | K31: £10% | L31: ='Calculations 48Gy4F_ or_ 60Gy5F'!K34 -> ?? | M31: RTOG 0813 and 0236 (Deviations NONE=10%, MINOR=15%) | O31: =CONCATENATE(C37," ",F38) -> Artery-Pulmonary V40Gy= | P31: =G38 -> ??
C32: Lung-Basic Function | E32: V11.6Gy (cc) = | G32: ?? | K32: 1500 | L32: =IF(G32="??","??",IF(G32<=K32,"Yes","No")) -> ?? | M32: V11.6Gy ≤ 1500cc (R or L Lung) | O32: =CONCATENATE(C39," ",F39) -> Spinal Canal (max point dose) | P32: =G39 -> ??
C33: Lung-Pneumonitis | E33: V12.4Gy (cc) = | G33: ?? | K33: 1000 | L33: =IF(G33="??","??",IF(G33<=K33,"Yes","No")) -> ?? | M33: V11.6Gy ≤ 1500cc (R or L Lung) | O33: =CONCATENATE(C39," ",F40) -> Spinal Canal V20.8Gy= | P33: =G40 -> ??
C34: Other OARs | O34: =CONCATENATE(C39," ",F41) -> Spinal Canal V13.6Gy= | P34: =G41 -> ??
C35: Aorta | F35: (max point dose) | G35: ?? | K35: 4800 | L35: =IF(G35="??","??",IF(G35<=4800,"Yes","No")) -> ?? | M35: LUSTRE | O35: =CONCATENATE(C42," ",F42) -> Spinal Canal-PRV 5mm (max point dose) | P35: =G42 -> ??
D36: V40Gy £ 10cc | F36: V40Gy= | G36: ?? | K36: 10 | L36: =IF(G36="??","??",IF(G36<=10,"Yes",IF(G36="OK","Yes","No"))) -> ?? | M36: LUSTRE | O36: =CONCATENATE(C43," ",F43) -> Ipsilat. Brach. Plex. (max point dose) | P36: =G43 -> ??
C37: Artery-Pulmonary | F37: (max point dose) | G37: ?? | K37: 4800 | L37: =IF(G37="??","??",IF(G37<=4800,"Yes","No")) -> ?? | M37: LUSTRE | O37: =CONCATENATE(C43," ",F44) -> Ipsilat. Brach. Plex. V23.6Gy= | P37: =G44 -> ??
D38: V40Gy £ 10cc | F38: V40Gy= | G38: ?? | K38: 10 | L38: =IF(G38="??","??",IF(G38<=10,"Yes",IF(G38="OK","Yes","No"))) -> ?? | M38: LUSTRE | O38: =CONCATENATE(C45," ",F45) -> Skin V30Gy= | P38: =G45 -> ??
C39: Spinal Canal | F39: (max point dose) | G39: ?? | K39: 2600 | L39: =IF(G39="??","??",IF(G39<=2600,"Yes","No")) -> ?? | M39: RTOG 0915 | O39: =CONCATENATE(C46," ",F46) -> Heart (max point dose) | P39: =G46 -> ??
D40: V20.8Gy £ 0.35cc | F40: V20.8Gy= | G40: ?? | K40: 0.35 | L40: =IF(G40="??","??",IF(G40<=0.35,"Yes",IF(G40="OK","Yes","No"))) -> ?? | M40: RTOG 0915 | O40: =CONCATENATE(C46," ",F47) -> Heart V28Gy= | P40: =G47 -> ??
D41: V13.6Gy £ 1.2cc | F41: V13.6Gy= | G41: ?? | K41: 1.2 | L41: =IF(G41="??","??",IF(G41<=1.2,"Yes",IF(G41="OK","Yes","No"))) -> ?? | M41: RTOG 0915 | O41: =CONCATENATE(C48," ",F48) -> Esophagus (max point dose) | P41: =G48 -> ??
...

Sheet EvaluationSheet 60Gy 8F
B1: NOTE: Must fill in information in YELLOW cells with "??". | H1: Use the ORIGINAL file for each NEW PLAN or modification
G2: SABR Plan Evaluation Sheet for 7.5Gy/fr Schedules: (60 Gy in 8F)
G3: (Tumours located within the lung parenchyma, away from the OAR’s and chest wall)
C4: Patient: | D4: ?? | F4: Prescription Dose (cGy): | H4: ?? | K4: Site: | L4: ?? | O4: =C4 -> Patient: | P4: =D4 -> ??
C5: CR#: | D5: ?? | F5: Fractions: | H5: ?? | K5: Plan Name: | L5: ?? | O5: =C5 -> CR#: | P5: =D5 -> ??
B6: Target/OAR Volumes: | O6: =K4 -> Site: | P6: =L4 -> ??
C7: GTV Volume (cc) | G7: ?? | O7: =K5 -> Plan Name: | P7: =L5 -> ??
C8: ITV Volume (cc): | G8: ?? | O8: =F4 -> Prescription Dose (cGy): | P8: =H4 -> ??
C9: PTV Volume (cc) | G9: ?? | O9: =F5 -> Fractions: | P9: =H5 -> ??
C10: Total Lung Volume (cc) | G10: ?? | O10: =C7 -> GTV Volume (cc) | P10: =G7 -> ??
B11: Normalization: | E11: 100% Dose covers 95% of Target Volume | O11: =C8 -> ITV Volume (cc): | P11: =G8 -> ??
G12: Ref Dose (%) / | H12: Calculated Value | I12: Calculated | K12: Protocol | L12: Acceptable | M12: Comments | O12: =C9 -> PTV Volume (cc) | P12: =G9 -> ??
G13: Ref Volume (cc) | K13: Requirement | O13: =C10 -> Total Lung Volume (cc) | P13: =G10 -> ??
C14: Plan Normalization Value (%) | G14: ?? | K14: 60%-95% | L14: =IF(G14="??","??",IF((AND((G14>59.99%),(G14<95.01%))),"Yes", "No")) -> ?? | M14: See "Prescription" on Eclipse | O14: =C14 -> Plan Normalization Value (%) | P14: =G14 -> ??
B16: PTV Dose Inhomogeneity: | O16: =C17 -> PTV- Minimum Dose | P16: =G17 -> ??
C17: PTV- Minimum Dose | G17: ?? | K17: 60%-95% | L17: =IF(G17="??","??",IF((AND((G17>=60%),(G17<=95%))),"Yes", "No")) -> ?? | O17: =C18 -> PTV - V100(%) | P17: =G18 -> ??
C18: PTV - V100(%) | G18: ?? | K18: 0.95 | L18: =IF(G18="??","??",(IF(G18>=95%,"Yes","No"))) -> ?? | M18: PTV (V48Gy) | O18: =C19 -> PTV - V90 (%) | P18: =G19 -> ??
C19: PTV - V90 (%) | G19: ?? | K19: 0.99 | L19: =IF(G19="??","??",(IF(G19>=99%,"Yes","No"))) -> ?? | M19: PTV (V43.2Gy) | O19: =CONCATENATE(C21," ",D21) -> Location V105% - PTV (cc) = | P19: =G21 -> ??
B20: HIGH Dose Spillage: | O20: =CONCATENATE(C22," ",D22) -> Volume V100% (cc) = | P20: =G22 -> ??
C21: Location | D21: V105% - PTV (cc) = | G21: ?? | H21: =IFERROR(G21/G9,"??") -> ?? | K21: <15% | L21: =IF(G21="??","??",IF(H21<15%,"Yes","No")) -> ?? | M21: Volume of the structure (Dose 105% - PTV), D105% = 50.4 Gy | O21: =CONCATENATE(C24," ",D24) -> Location D³2cm (%) = | P21: =G24 -> ??
C22: Volume | D22: V100% (cc) = | G22: ?? | H22: =IFERROR(G22/G9,"??") -> ?? | K22: <1.2 | L22: ='Calculations 60Gy_8F'!K31 -> ?? | M22: Ratio VD100%/VPTV (On DVH see BODY volume for 100% prescription dose) | O22: =CONCATENATE(C25," ",D25) -> Volume V50% (cc) = | P22: =G25 -> ??
B23: LOW Dose Spillage: | O23: =C29 -> Mean Dose (contralateral lung) | P23: =G29 -> ??
C24: Location | D24: D³2cm (%) = | G24: ?? | K24: =IFERROR('Calculations 60Gy_8F'!L27/100,"??") -> ?? | L24: ='Calculations 60Gy_8F'!K33 -> ?? | M24: Max dose (in %) ³2cm from PTV (structure BODY-(PTV+2cm)), should be £ R50 value in Table 1, MINOR deviation acceptable | O24: =C30 -> Mean Dose (Total lung) | P24: =G30 -> ??
C25: Volume | D25: V50% (cc) = | G25: ?? | H25: =IFERROR(G25/G9,"??") -> ?? | K25: =IFERROR('Calculations 60Gy_8F'!I27,"??") -> ?? | L25: ='Calculations 60Gy_8F'!K32 -> ?? | M25: Ratio VD50%/VPTV should be£ R50 value in Table 1, MINOR deviation acceptable | O25: =C31 -> V20 (Total Lung) | P25: =G31 -> ??
B26: DOSE TO OARs | G26: Maximum Dose (cGy) | H26: Calculated Value | K26: Tolerance | O26: =CONCATENATE(C33," ",F33) -> Aorta (max point dose) | P26: =G33 -> ??
G27: / Volume (cc) | K27: (cGy) / (cc) | O27: =CONCATENATE(C33," ",F34) -> Aorta V60Gy= | P27: =G34 -> ??
C28: Lung Dose | O28: =CONCATENATE(C35," ",F35) -> Artery-Pulmonary (max point dose) | P28: =G35 -> ??
C29: Mean Dose (contralateral lung) | G29: ?? | L29: ?? | O29: =CONCATENATE(C35," ",F36) -> Artery-Pulmonary V60Gy= | P29: =G36 -> ??
C30: Mean Dose (Total lung) | G30: ?? | L30: ?? | O30: =CONCATENATE(C37," ",F37) -> Spinal Canal (max point dose) | P30: =G37 -> ??
C31: V20 (Total Lung) | E31: V20Gy (%) = | G31: ?? | K31: £10% | L31: ='Calculations 60Gy_8F'!K34 -> ?? | M31: RTOG 0813 and 0236 (Deviations NONE=10%, MINOR=15%) | O31: =CONCATENATE(C38," ",F38) -> Ipsilat. Brach. Plex. (max point dose) | P31: =G38 -> ??
C32: Other OARs | O32: =CONCATENATE(C38," ",F39) -> Ipsilat. Brach. Plex. V30Gy= | P32: =G39 -> ??
C33: Aorta | F33: (max point dose) | G33: ?? | K33: 6400 | L33: =IF(G33="??","??",IF(G33<=6400,"Yes","No")) -> ?? | M33: LUSTRE | O33: =CONCATENATE(C40," ",F40) -> Heart (max point dose) | P33: =G40 -> ??
D34: V60Gy £ 10cc | F34: V60Gy= | G34: ?? | K34: 10 | L34: =IF(G34="??","??",IF(G34<=10,"Yes",IF(G34="OK","Yes","No"))) -> ?? | O34: =CONCATENATE(C40," ",F41) -> Heart V60Gy= | P34: =G41 -> ??
C35: Artery-Pulmonary | F35: (max point dose) | G35: ?? | K35: 6400 | L35: =IF(G35="??","??",IF(G35<=6400,"Yes","No")) -> ?? | M35: LUSTRE | O35: =CONCATENATE(C42," ",F42) -> Esophagus (max point dose) | P35: =G42 -> ??
D36: V60Gy £ 10cc | F36: V60Gy= | G36: ?? | K36: 10 | L36: =IF(G36="??","??",IF(G36<=10,"Yes",IF(G36="OK","Yes","No"))) -> ?? | O36: =CONCATENATE(C43," ",F43) -> Chestwall (rib) (max point dose) | P36: =G43 -> ??
C37: Spinal Canal | F37: (max point dose) | G37: ?? | K37: 3200 | L37: =IF(G37="??","??",IF(G37<=3200,"Yes","No")) -> ?? | M37: RTOG0236 | O37: =CONCATENATE(C43," ",F44) -> Chestwall (rib) V50Gy= | P37: =G44 -> ??
C38: Ipsilat. Brach. Plex. | F38: (max point dose) | G38: ?? | K38: 3800 | L38: =IF(G38="??","??",IF(G38<=3800,"Yes","No")) -> ?? | M38: LUSTRE | O38: =CONCATENATE(A44," ",F45) -> Trachea (max point dose) | P38: =A45 -> ??
D39: V30Gy £ 3cc | F39: V30Gy= | G39: ?? | K39: 3 | L39: =IF(G39="??","??",IF(G39<=3,"Yes",IF(G39="OK","Yes","No"))) -> ?? | O39: =CONCATENATE(A44," ",F46) -> Trachea V60Gy = | P39: =A46 -> ??
C40: Heart | F40: (max point dose) | G40: ?? | K40: 6400 | L40: =IF(G40="??","??",IF(G40<=6400,"Yes","No")) -> ?? | M40: RTOG0236 | O40: =CONCATENATE(B44," ",F45) -> Bronchus (max point dose) | P40: =B45 -> ??
D41: V60Gy £ 10cc | F41: V60Gy= | G41: ?? | K41: 10 | L41: =IF(G41="??","??",IF(G41<=10,"Yes",IF(G41="OK","Yes","No"))) -> ?? | M41: LUSTRE | O41: =CONCATENATE(B44," ",F48) -> Bronchus V36Gy= | P41: =B46 -> ??
...

Sheet EvaluationSheet 54Gy 3F
B1: NOTE: Must fill in information in YELLOW cells with "??". | H1: Use the ORIGINAL file for each NEW PLAN or modification
G2: SABR Plan Evaluation Sheet for 18Gy/fr Schedules (54Gy/3F)
G3: (Tumours located within the lung parenchyma, away from the OAR’s and chest wall)
C4: Patient: | D4: ?? | F4: Prescription Dose (cGy): | H4: 5400 | K4: Site: | L4: ?? | O4: =C4 -> Patient: | P4: =D4 -> ??
C5: CR#: | D5: ?? | F5: Fractions: | H5: 3 | K5: Plan Name: | L5: ?? | O5: =C5 -> CR#: | P5: =D5 -> ??
B6: Target/OAR Volumes: | O6: =K4 -> Site: | P6: =L4 -> ??
C7: GTV Volume (cc) | G7: ?? | O7: =K5 -> Plan Name: | P7: =L5 -> ??
C8: ITV Volume (cc): | G8: ?? | O8: =F4 -> Prescription Dose (cGy): | P8: =H4 -> 5400
C9: PTV Volume (cc) | G9: ?? | O9: =F5 -> Fractions: | P9: =H5 -> 3
C10: Total Lung Volume (cc) | G10: ?? | O10: =C7 -> GTV Volume (cc) | P10: =G7 -> ??
B11: Normalization: | E11: 100% Dose covers 95% of Target Volume | O11: =C8 -> ITV Volume (cc): | P11: =G8 -> ??
G12: ref Dose (cGy or %) / | H12: Calculated/Plan | I12: Calculated | K12: Protocol | L12: Acceptable | M12: Comments | O12: =C9 -> PTV Volume (cc) | P12: =G9 -> ??
G13: ref volume (cc) | K13: Requirement | O13: =C10 -> Total Lung Volume (cc) | P13: =G10 -> ??
C14: Plan Normalization Value (%) | G14: =IFERROR(H14*$H$4,"??") -> ?? | H14: ?? | I14: =AND((H14>59.99%),(H14<90.01%)) -> FALSE | K14: 60%-90% | L14: =IF(I14=TRUE, "Yes", "No") -> No | M14: See "Prescription" on Eclipse | O14: =C14 -> Plan Normalization Value (%) | P14: =H14 -> ??
B16: PTV Dose Inhomogeneity: | O16: =C17 -> PTV- Minimum Dose | P16: =G17 -> ??
C17: PTV- Minimum Dose | G17: ?? | H17: =IFERROR(G17/$H$4,"??") -> ?? | I17: =AND((H17>59.99%),(H17<90.01%)) -> FALSE | K17: 60%-90% | L17: =IF(I17=TRUE, "Yes", "No") -> No | O17: =C18 -> PTV - V100(%) | P17: =H18 -> ??
C18: PTV - V100(%) | G18: =H4 -> 5400 | H18: ?? | K18: 0.95 | L18: =IF(H18>=K18,"Yes","No") -> Yes | M18: PTV (V54Gy) | O18: =C19 -> PTV - V90 (%) | P18: =H19 -> ??
C19: PTV - V90 (%) | G19: =0.9*H4 -> 4860 | H19: ?? | K19: 0.99 | L19: =IF(H19>=K19,"Yes","No") -> Yes | M19: PTV (V48.6Gy) | O19: =CONCATENATE(C21," ",D21) -> Location V105% - PTV (cc) = | P19: =G21 -> ??
B20: HIGH Dose Spillage: | O20: =CONCATENATE(C22," ",D22) -> Volume V100% (cc) = | P20: =G22 -> ??
C21: Location | D21: V105% - PTV (cc) = | G21: ?? | H21: =IFERROR(G21/G9,"??") -> ?? | K21: <15% | L21: =IF(H21<=15%,"Yes","No") -> No | M21: Volume of the structure (Dose 105% - PTV), D105%=56.7Gy | O21: =CONCATENATE(C24," ",D24) -> Location D³2cm (%) = | P21: =G24 -> ??
C22: Volume | D22: V100% (cc) = | G22: ?? | H22: =IFERROR('Calculations 54Gy 3F'!J31,"??") -> ?? | K22: <1.2 | L22: =IFERROR('Calculations 54Gy 3F'!K31,"No") -> No | M22: Ratio VD100%/VPTV (On DVH see BODY volume for 100% prescription dose) | O22: =C25 -> Volume(R50) | P22: =G25 -> ??
B23: LOW Dose Spillage: | O23: =C29 -> Mean Dose (contralateral lung) | P23: =G29 -> ??
C24: Location | D24: D³2cm (%) = | G24: ?? | H24: =IFERROR(G24/H4,"??") -> ?? | K24: =IFERROR('Calculations 54Gy 3F'!L27/100,"??") -> ?? | L24: =IFERROR('Calculations 54Gy 3F'!K33,"No") -> No | M24: Max dose (in %) ³2cm from PTV (structure BODY-(PTV+2cm)), should be £ R50 value (None) in Table 1, MINOR deviation acceptable in rare cases | O24: =C30 -> Mean Dose (Total lung) | P24: =G30 -> ??
C25: Volume(R50) | F25: V50% (cc) = | G25: ?? | H25: =IFERROR('Calculations 54Gy 3F'!J32,"??") -> ?? | K25: =IFERROR('Calculations 54Gy 3F'!I27,"??") -> ?? | L25: =IFERROR('Calculations 54Gy 3F'!K32,"No") -> No | M25: Ratio VD50%/VPTV should be£ R50 value (None) in Table 1, MINOR deviation acceptable in rare cases (On DVH see BODY volume for 50% prescription dose) | O25: =C31 -> V20 (Total Lung) in % | P25: =G31 -> ??
B26: DOSE TO OARs | G26: Maximum Point | H26: Calculated/Plan | K26: Tolerance | O26: =CONCATENATE(C32," ",F32) -> Lung-Basic Function V11.6Gy= | P26: =G32 -> ??
G27: Dose (cGy) | K27: Max Dose (cGy)/ volume | O27: =CONCATENATE(C33," ",F33) -> Lung-Pneumonitis V12.4Gy= | P27: =G33 -> ??
C28: Lung Dose | O28: =CONCATENATE(C35," ",F35) -> Aorta (max point dose) | P28: =G35 -> ??
C29: Mean Dose (contralateral lung) | G29: ?? | O29: =CONCATENATE(C36," ",F35) -> Artery-Pulmnory (max point dose) | P29: =G36 -> ??
C30: Mean Dose (Total lung) | G30: ?? | O30: =CONCATENATE(C37," ",F37) -> Spinal Canal (max point dose) | P30: =G37 -> ??
C31: V20 (Total Lung) in % | F31: V20Gy (%)= | G31: ?? | K31: =IFERROR('Calculations 54Gy 3F'!O27,"??") -> ?? | L31: =IFERROR('Calculations 54Gy 3F'!K34,"No") -> No | M31: RTOG 0813 and 0236 (Deviations NONE=10%, MINOR=15%) | O31: =CONCATENATE(C38," ",F37) -> Spinal Canal-PRV 5mm (max point dose) | P31: =G38 -> ??
C32: Lung-Basic Function | F32: V11.6Gy= | G32: ?? | H32: V11.6Gy≤1500cc (R or L Lung) | K32: 1500 | L32: =IF(G32<=K32,"Yes","No") -> No | M32: R or L Lung volume getting >1160cGy | O32: =CONCATENATE(C39," ",F39) -> Ipsilat Brach.Plex (max point dose) | P32: =G39 -> ??
C33: Lung-Pneumonitis | F33: V12.4Gy= | G33: ?? | H33: V12.4Gy≤1500cc (R or L Lung) | K33: 1000 | L33: =IF(G33<=K33,"Yes","No") -> No | M33: R or L Lung volume getting>1240cGy | O33: =CONCATENATE(C40," ",F40) -> Skin V30Gy= | P33: =G40 -> ??
C34: Other OARs | O34: =CONCATENATE(C41," ",F41) -> Heart (max point dose) | P34: =G41 -> ??
C35: Aorta | F35: (max point dose) | G35: ?? | K35: 3000 | L35: =IF(G35<=K35,"Yes","No") -> No | O35: =CONCATENATE(C42," ",F42) -> Esophagus (max point dose) | P35: =G42 -> ??
C36: Artery-Pulmnory | G36: ?? | K36: 3000 | L36: =IF(G36<=K36,"Yes","No") -> No | O36: =CONCATENATE(C43," ",F43) -> *Chestwall (rib) (max point dose) | P36: =G43 -> ??
C37: Spinal Canal | F37: (max point dose) | G37: ?? | K37: 1800 | L37: =IF(G37<=K37,"Yes","No") -> No | M37: RTOG 0915 | O37: =CONCATENATE(C43," ",F44) -> *Chestwall (rib) V28.2Gy= | P37: =G44 -> ??
C38: Spinal Canal-PRV 5mm | G38: ?? | K38: 2000 | L38: =IF(G38<=K38,"Yes","No") -> No | O38: =CONCATENATE(C43," ",F45) -> *Chestwall (rib) V30Gy= | P38: =G45 -> ??
C39: Ipsilat Brach.Plex | F39: (max point dose) | G39: ?? | K39: 2400 | L39: =IF(G39<=K39,"Yes","No") -> No | M39: RTOG0236 | O39: =A46 -> Trachea | P39: =A47 -> 0
C40: Skin | D40: V30Gy£10cc | F40: V30Gy= | G40: ?? | K40: 10 | L40: =IF(G40<=K40,"Yes","No") -> No | M40: RTOG0236 | O40: =B46 -> Bronchus | P40: =B47 -> 0
C41: Heart | F41: (max point dose) | G41: ?? | K41: 3000 | L41: =IF(G41<=K41,"Yes","No") -> No | M41: RTOG0915 | O41: =CONCATENATE(C46," ",C47," ",F46) -> Proximal Trachea and Bronchial Tree (max point dose) | P41: =G46 -> ??
...

Sheet Calculations 48Gy4F_ or_ 60Gy5F
I1: RTOG 0813: Conformality Table
E2: Table 1: Conformality of Prescribed Dose for Calculations Based on Deposition of Photon Beam Energy in Heterogeneous Tissue
L3: Maximum Dose (in % | O3: Percent of Lung Receiving
F4: Ratio of Prescription | I4: Ratio of 50% Isodose | L4: of dose prescribed) @ 2cm | O4: 20 Gy Total or More,
F5: Isodose Volume to the | I5: Volume to the PTV Volume | L5: from PTV in Any Direction
D6: PTV Volume | F6: PTV Volume
D7: Vptv | F7: (Vptv/V100) | J7: R50% | L7: D2cm (Gy) | O7: V20 (%)
D8: (cc) | F8: None | G8: Minor Deviation | I8: None | J8: Minor Deviation | L8: None | M8: Minor Deviation | O8: None | P8: Minor Deviation
D9: 1.8 | F9: 1.2 | G9: 1.5 | I9: 5.9 | J9: 7.5 | L9: 50 | M9: 57 | O9: 10 | P9: 15
D10: 3.8 | F10: 1.2 | G10: 1.5 | I10: 5.5 | J10: 6.5 | L10: 50 | M10: 57 | O10: 10 | P10: 15
D11: 7.4 | F11: 1.2 | G11: 1.5 | I11: 5.1 | J11: 6 | L11: 50 | M11: 58 | O11: 10 | P11: 15
D12: 13.2 | F12: 1.2 | G12: 1.5 | I12: 4.7 | J12: 5.8 | L12: 50 | M12: 58 | O12: 10 | P12: 15
D13: 22 | F13: 1.2 | G13: 1.5 | I13: 4.5 | J13: 5.5 | L13: 54 | M13: 63 | O13: 10 | P13: 15
D14: 34 | F14: 1.2 | G14: 1.5 | I14: 4.3 | J14: 5.3 | L14: 58 | M14: 68 | O14: 10 | P14: 15
D15: 50 | F15: 1.2 | G15: 1.5 | I15: 4 | J15: 5 | L15: 62 | M15: 77 | O15: 10 | P15: 15
D16: 70 | F16: 1.2 | G16: 1.5 | I16: 3.5 | J16: 4.8 | L16: 66 | M16: 86 | O16: 10 | P16: 15
D17: 95 | F17: 1.2 | G17: 1.5 | I17: 3.3 | J17: 4.4 | L17: 70 | M17: 89 | O17: 10 | P17: 15
D18: 126 | F18: 1.2 | G18: 1.5 | I18: 3.1 | J18: 4 | L18: 73 | M18: 91 | O18: 10 | P18: 15
D19: 163 | F19: 1.2 | G19: 1.5 | I19: 2.9 | J19: 3.7 | L19: 77 | M19: 94 | O19: 10 | P19: 15
C21: Note 1: For values of PTV dimension or volume not specified, linear interpolation between table entries is required.
C22: Note 2: Protocol deviations greater than listed here as “minor” will be classified as “major” for protocol compliance (see Section 6.7).
C24: INTERPOLATIONS
F25: Interpolation Vptv/V100% | I25: Interpolation Vptv/V100% | L25: Interpolation D2cm | O25: Interpolation V20Gy
F26: Yes | G26: Minor Deviation | H26: MAJOR Deviation | I26: Yes | J26: Minor Deviation | K26: MAJOR Deviation | L26: Yes | M26: Minor Deviation | N26: MAJOR Deviation | O26: Yes | P26: Minor Deviation | Q26: MAJOR Deviation
F27: =FORECAST(I30,OFFSET(F9:F19,MATCH(I30,D9:D19,1)-1,0,2),OFFSET(D9:D19,MATCH(I30,D9:D19,1)-1,0,2)) -> #VALUE! | G27: =FORECAST(I30,OFFSET(G9:G19,MATCH(I30,D9:D19,1)-1,0,2),OFFSET(D9:D19,MATCH(I30,D9:D19,1)-1,0,2)) -> #VALUE! | I27: =FORECAST(I30,OFFSET(I9:I19,MATCH(I30,D9:D19,1)-1,0,2),OFFSET(D9:D19,MATCH(I30,D9:D19,1)-1,0,2)) -> #VALUE! | J27: =FORECAST(I30,OFFSET(J9:J19,MATCH(I30,D9:D19,1)-1,0,2),OFFSET(D9:D19,MATCH(I30,D9:D19,1)-1,0,2)) -> #VALUE! | L27: =FORECAST(I30,OFFSET(L9:L19,MATCH(I30,D9:D19,1)-1,0,2),OFFSET(D9:D19,MATCH(I30,D9:D19,1)-1,0,2)) -> #VALUE! | M27: =FORECAST(I30,OFFSET(M9:M19,MATCH(I30,D9:D19,1)-1,0,2),OFFSET(D9:D19,MATCH(I30,D9:D19,1)-1,0,2)) -> #VALUE! | O27: =FORECAST(I30,OFFSET(O9:O19,MATCH(I30,D9:D19,1)-1,0,2),OFFSET(D9:D19,MATCH(I30,D9:D19,1)-1,0,2)) -> #VALUE! | P27: =FORECAST(I30,OFFSET(P9:P19,MATCH(I30,D9:D19,1)-1,0,2),OFFSET(D9:D19,MATCH(I30,D9:D19,1)-1,0,2)) -> #VALUE!
C28: CALCULATIONS
I29: value | J29: ratio | K29: pass/fail/deviation
H30: PTV Volume Vptv(cc) | I30: ='EvaluationSheet 48Gy4F 60Gy5F'!G9 -> ??
H31: V100% | I31: ='EvaluationSheet 48Gy4F 60Gy5F'!G22 -> ?? | J31: =I31/I30 -> #VALUE! | K31: =IF(I31="??","??",IF(J31<F27,F26,IF(J31<=G27,G26,H26))) -> ??
H32: R50% (cc) | I32: ='EvaluationSheet 48Gy4F 60Gy5F'!G25 -> ?? | J32: =I32/I30 -> #VALUE! | K32: =IF(I32="??","??",IF(J32<=I27,I26,IF(J32<=J27,J26,K26))) -> ??
H33: D2cm (%) | I33: ='EvaluationSheet 48Gy4F 60Gy5F'!G24 -> ?? | J33: =I33 -> ?? | K33: =IF(I33="??","??",IF(J33<=L27,L26,IF(J33<=M27,M26,N26))) -> ??
H34: Lung V20Gy | I34: ='EvaluationSheet 48Gy4F 60Gy5F'!G31 -> ?? | K34: =IF(I34="??","??",IF(I34<=0.1,O26,IF(I34<=0.15,P26,Q26))) -> ??
C43: Q:\SBRT\Policy\SABR Plan Evaluation Worksheet 4Dec2013.xls

Sheet Calculations 60Gy_8F
I1: RTOG 0813: Conformality Table
E2: Table 1: Conformality of Prescribed Dose for Calculations Based on Deposition of Photon Beam Energy in Heterogeneous Tissue
L3: Maximum Dose (in % | O3: Percent of Lung Receiving
F4: Ratio of Prescription | I4: Ratio of 50% Isodose | L4: of dose prescribed) @ 2cm | O4: 20 Gy Total or More,
F5: Isodose Volume to the | I5: Volume to the PTV Volume | L5: from PTV in Any Direction
D6: PTV Volume | F6: PTV Volume
D7: Vptv | F7: (Vptv/V100) | J7: R50% | L7: D2cm (Gy) | O7: V20 (%)
D8: (cc) | F8: None | G8: Minor Deviation | I8: None | J8: Minor Deviation | L8: None | M8: Minor Deviation | O8: None | P8: Minor Deviation
D9: 1.8 | F9: 1.2 | G9: 1.5 | I9: 5.9 | J9: 7.5 | L9: 50 | M9: 57 | O9: 10 | P9: 15
D10: 3.8 | F10: 1.2 | G10: 1.5 | I10: 5.5 | J10: 6.5 | L10: 50 | M10: 57 | O10: 10 | P10: 15
D11: 7.4 | F11: 1.2 | G11: 1.5 | I11: 5.1 | J11: 6 | L11: 50 | M11: 58 | O11: 10 | P11: 15
D12: 13.2 | F12: 1.2 | G12: 1.5 | I12: 4.7 | J12: 5.8 | L12: 50 | M12: 58 | O12: 10 | P12: 15
D13: 22 | F13: 1.2 | G13: 1.5 | I13: 4.5 | J13: 5.5 | L13: 54 | M13: 63 | O13: 10 | P13: 15
D14: 34 | F14: 1.2 | G14: 1.5 | I14: 4.3 | J14: 5.3 | L14: 58 | M14: 68 | O14: 10 | P14: 15
D15: 50 | F15: 1.2 | G15: 1.5 | I15: 4 | J15: 5 | L15: 62 | M15: 77 | O15: 10 | P15: 15
D16: 70 | F16: 1.2 | G16: 1.5 | I16: 3.5 | J16: 4.8 | L16: 66 | M16: 86 | O16: 10 | P16: 15
D17: 95 | F17: 1.2 | G17: 1.5 | I17: 3.3 | J17: 4.4 | L17: 70 | M17: 89 | O17: 10 | P17: 15
D18: 126 | F18: 1.2 | G18: 1.5 | I18: 3.1 | J18: 4 | L18: 73 | M18: 91 | O18: 10 | P18: 15
D19: 163 | F19: 1.2 | G19: 1.5 | I19: 2.9 | J19: 3.7 | L19: 77 | M19: 94 | O19: 10 | P19: 15
C21: Note 1: For values of PTV dimension or volume not specified, linear interpolation between table entries is required.
C22: Note 2: Protocol deviations greater than listed here as “minor” will be classified as “major” for protocol compliance (see Section 6.7).
C24: INTERPOLATIONS
F25: Interpolation Vptv/V100% | I25: Interpolation Vptv/V100% | L25: Interpolation D2cm | O25: Interpolation D2cm
F26: Yes | G26: Minor Deviation | H26: MAJOR Deviation | I26: Yes | J26: Minor Deviation | K26: MAJOR Deviation | L26: Yes | M26: Minor Deviation | N26: MAJOR Deviation | O26: Yes | P26: Minor Deviation | Q26: MAJOR Deviation
F27: =FORECAST(I30,OFFSET(F9:F19,MATCH(I30,D9:D19,1)-1,0,2),OFFSET(D9:D19,MATCH(I30,D9:D19,1)-1,0,2)) -> #VALUE! | G27: =FORECAST(I30,OFFSET(G9:G19,MATCH(I30,D9:D19,1)-1,0,2),OFFSET(D9:D19,MATCH(I30,D9:D19,1)-1,0,2)) -> #VALUE! | I27: =FORECAST(I30,OFFSET(I9:I19,MATCH(I30,D9:D19,1)-1,0,2),OFFSET(D9:D19,MATCH(I30,D9:D19,1)-1,0,2)) -> #VALUE! | J27: =FORECAST(I30,OFFSET(J9:J19,MATCH(I30,D9:D19,1)-1,0,2),OFFSET(D9:D19,MATCH(I30,D9:D19,1)-1,0,2)) -> #VALUE! | L27: =FORECAST(I30,OFFSET(L9:L19,MATCH(I30,D9:D19,1)-1,0,2),OFFSET(D9:D19,MATCH(I30,D9:D19,1)-1,0,2)) -> #VALUE! | M27: =FORECAST(I30,OFFSET(M9:M19,MATCH(I30,D9:D19,1)-1,0,2),OFFSET(D9:D19,MATCH(I30,D9:D19,1)-1,0,2)) -> #VALUE! | O27: =FORECAST(I30,OFFSET(O9:O19,MATCH(I30,D9:D19,1)-1,0,2),OFFSET(D9:D19,MATCH(I30,D9:D19,1)-1,0,2)) -> #VALUE! | P27: =FORECAST(I30,OFFSET(P9:P19,MATCH(I30,D9:D19,1)-1,0,2),OFFSET(D9:D19,MATCH(I30,D9:D19,1)-1,0,2)) -> #VALUE!
C28: CALCULATIONS
I29: value | J29: ratio | K29: pass/fail/deviation
H30: PTV Volume Vptv(cc) | I30: ='EvaluationSheet 60Gy 8F'!G9 -> ??
H31: V100% | I31: ='EvaluationSheet 60Gy 8F'!G22 -> ?? | J31: =I31/I30 -> #VALUE! | K31: =IF(I31="??","??",IF(J31<F27,F26,IF(J31<=G27,G26,H26))) -> ??
H32: R50% (cc) | I32: ='EvaluationSheet 60Gy 8F'!G25 -> ?? | J32: =I32/I30 -> #VALUE! | K32: =IF(I32="??", "??",IF(J32<=I27,I26,IF(J32<=J27,J26,K26))) -> ??
H33: D2cm (%) | I33: ='EvaluationSheet 60Gy 8F'!G24 -> ?? | J33: =I33 -> ?? | K33: =IF(I33="??","??",IF(J33<=L27,L26,IF(J33<=M27,M26,N26))) -> ??
H34: Lung V20Gy | I34: ='EvaluationSheet 60Gy 8F'!G31 -> ?? | K34: =IF(I34="??","??",IF(I34<=0.1,O26,IF(I34<=0.15,P26,Q26))) -> ??
C46: Q:\SBRT\Policy\SABR Plan Evaluation Worksheet 4Dec2013.xls

Sheet Calculations 54Gy 3F
I1: RTOG 0813: Conformality Table
E2: Table 1: Conformality of Prescribed Dose for Calculations Based on Deposition of Photon Beam Energy in Heterogeneous Tissue
L3: Maximum Dose (in % | O3: Percent of Lung Receiving
F4: Ratio of Prescription | I4: Ratio of 50% Isodose | L4: of dose prescribed) @ 2cm | O4: 20 Gy Total or More,
F5: Isodose Volume to the | I5: Volume to the PTV Volume | L5: from PTV in Any Direction
D6: PTV Volume | F6: PTV Volume
D7: Vptv | F7: (Vptv/V100) | J7: R50% | L7: D2cm (Gy) | O7: V20 (%)
D8: (cc) | F8: None | G8: Minor Deviation | I8: None | J8: Minor Deviation | L8: None | M8: Minor Deviation | O8: None | P8: Minor Deviation
D9: 1.8 | F9: 1.2 | G9: 1.5 | I9: 5.9 | J9: 7.5 | L9: 50 | M9: 57 | O9: 10 | P9: 15
D10: 3.8 | F10: 1.2 | G10: 1.5 | I10: 5.5 | J10: 6.5 | L10: 50 | M10: 57 | O10: 10 | P10: 15
D11: 7.4 | F11: 1.2 | G11: 1.5 | I11: 5.1 | J11: 6 | L11: 50 | M11: 58 | O11: 10 | P11: 15
D12: 13.2 | F12: 1.2 | G12: 1.5 | I12: 4.7 | J12: 5.8 | L12: 50 | M12: 58 | O12: 10 | P12: 15
D13: 22 | F13: 1.2 | G13: 1.5 | I13: 4.5 | J13: 5.5 | L13: 54 | M13: 63 | O13: 10 | P13: 15
D14: 34 | F14: 1.2 | G14: 1.5 | I14: 4.3 | J14: 5.3 | L14: 58 | M14: 68 | O14: 10 | P14: 15
D15: 50 | F15: 1.2 | G15: 1.5 | I15: 4 | J15: 5 | L15: 62 | M15: 77 | O15: 10 | P15: 15
D16: 70 | F16: 1.2 | G16: 1.5 | I16: 3.5 | J16: 4.8 | L16: 66 | M16: 86 | O16: 10 | P16: 15
D17: 95 | F17: 1.2 | G17: 1.5 | I17: 3.3 | J17: 4.4 | L17: 70 | M17: 89 | O17: 10 | P17: 15
D18: 126 | F18: 1.2 | G18: 1.5 | I18: 3.1 | J18: 4 | L18: 73 | M18: 91 | O18: 10 | P18: 15
D19: 163 | F19: 1.2 | G19: 1.5 | I19: 2.9 | J19: 3.7 | L19: 77 | M19: 94 | O19: 10 | P19: 15
C21: Note 1: For values of PTV dimension or volume not specified, linear interpolation between table entries is required.
C22: Note 2: Protocol deviations greater than listed here as “minor” will be classified as “major” for protocol compliance (see Section 6.7).
C24: INTERPOLATIONS
F25: Interpolation Vptv/V100% | I25: Interpolation Vptv/V100% | L25: Interpolation D2cm | O25: Interpolation D2cm
F26: Yes | G26: Minor Deviation | H26: MAJOR Deviation | I26: Yes | J26: Minor Deviation | K26: MAJOR Deviation | L26: Yes | M26: Minor Deviation | N26: MAJOR Deviation | O26: Yes | P26: Minor Deviation | Q26: MAJOR Deviation
F27: =FORECAST(I30,OFFSET(F9:F19,MATCH(I30,D9:D19,1)-1,0,2),OFFSET(D9:D19,MATCH(I30,D9:D19,1)-1,0,2)) -> #VALUE! | G27: =FORECAST(I30,OFFSET(G9:G19,MATCH(I30,D9:D19,1)-1,0,2),OFFSET(D9:D19,MATCH(I30,D9:D19,1)-1,0,2)) -> #VALUE! | I27: =FORECAST(I30,OFFSET(I9:I19,MATCH(I30,D9:D19,1)-1,0,2),OFFSET(D9:D19,MATCH(I30,D9:D19,1)-1,0,2)) -> #VALUE! | J27: =FORECAST(I30,OFFSET(J9:J19,MATCH(I30,D9:D19,1)-1,0,2),OFFSET(D9:D19,MATCH(I30,D9:D19,1)-1,0,2)) -> #VALUE! | L27: =FORECAST(I30,OFFSET(L9:L19,MATCH(I30,D9:D19,1)-1,0,2),OFFSET(D9:D19,MATCH(I30,D9:D19,1)-1,0,2)) -> #VALUE! | M27: =FORECAST(I30,OFFSET(M9:M19,MATCH(I30,D9:D19,1)-1,0,2),OFFSET(D9:D19,MATCH(I30,D9:D19,1)-1,0,2)) -> #VALUE! | O27: =FORECAST(I30,OFFSET(O9:O19,MATCH(I30,D9:D19,1)-1,0,2),OFFSET(D9:D19,MATCH(I30,D9:D19,1)-1,0,2)) -> #VALUE! | P27: =FORECAST(I30,OFFSET(P9:P19,MATCH(I30,D9:D19,1)-1,0,2),OFFSET(D9:D19,MATCH(I30,D9:D19,1)-1,0,2)) -> #VALUE!
C28: CALCULATIONS
I29: value | J29: ratio | K29: pass/fail/deviation
H30: PTV Volume Vptv(cc) | I30: ='EvaluationSheet 54Gy 3F'!G9 -> ??
H31: V100% | I31: ='EvaluationSheet 54Gy 3F'!G22 -> ?? | J31: =I31/I30 -> #VALUE! | K31: =IF(J31<=F27,F26,IF(J31<=G27,G26,H26)) -> #VALUE!
H32: R50% (cc) | I32: ='EvaluationSheet 54Gy 3F'!G25 -> ?? | J32: =I32/I30 -> #VALUE! | K32: =IF(J32<=I27,I26,IF(J32<=J27,J26,K26)) -> #VALUE!
H33: D2cm (%) | I33: ='EvaluationSheet 54Gy 3F'!G24 -> ?? | J33: =I33/'EvaluationSheet 54Gy 3F'!H4*100 -> #VALUE! | K33: =IF(J33<=L27,L26,IF(J33<=M27,M26,N26)) -> #VALUE!
H34: Lung V20Gy | I34: ='EvaluationSheet 54Gy 3F'!G31*100 -> #VALUE! | K34: =IF(I34<=O27,O26,IF(I34<=P27,P26,Q26)) -> #VALUE!
C43: Q:\SBRT\Policy\SABR Plan Evaluation Worksheet 4Dec2013.xls

Sheet RTOG Conformality Table
H2: RTOG 0813 | P2: Reference: EXCEL LOGICAL OPERATIONS
O3: http://www.blueleafsoftware.com/Products/Dagra/LinearInterpolationExcel.php
O5: FORECAST(NewX,OFFSET(KnownY,MATCH(NewX,KnownX,1)-1,0,2),
O6: OFFSET(KnownX,MATCH(NewX,KnownX,1)-1,0,2))
